Workbook

Sheet Read Me
A1: Church in Conversation — Phase 1 Budget
A2: Draft v0.1 · Built 2026-07-08 · For Mark&apos;s review, not yet final
A5: What this is | B5: A working budget model for Phase 1 (first public release — 5 Ancient Church worlds, public access begins, per CiC_L3A_Phase_Structure_V1.1). Built from real API pricing and the project&apos;s own engineering/governance documents, not invented from scratch.
A7: What it deliberately excludes | B7: No stipend for Mark is included anywhere in this budget, per his explicit instruction (2026-07-08). Add one later as a separate line when that&apos;s ready to be decided.
A9: How to use it | B9: Change any blue cell on the Assumptions tab to test a different scenario — everything else recalculates. Black cells are formulas; green cells pull from another sheet. Do not type over black or green cells.
A11: Confidence levels, stated honestly | B11: Some numbers here are Documented (real quoted API pricing, dated and sourced). Others are Inferential/Thin — reasoned estimates from adjacent market comparables, because no list price exists (contract engineering hours, reviewer honoraria, hosting at a platform that hasn&apos;t been chosen yet). Every assumption row on the Assumptions tab names its source and confidence level in the Notes column so nothing here is mistaken for more certain than it is.
A13: Two cost buckets, treated differently | B13: Bucket A (Unit Economics + Phase 1 Budget tabs) is usage-scaling cost — AI inference and voice generation, which scales with how many people use this and how much. It needs revenue that scales with usage too (subscriptions, donations, licensing). Bucket B is fixed/semi-fixed ministry cost — external scholarly reviewers, engineering build-out, hosting base fee — which scales with the number of worlds and features built, not with user count. It&apos;s better suited to grants and institutional partnerships. See the 2026-07-08 decision log entry for the full reasoning.
A15: Biggest open uncertainty | B15: Per Mark&apos;s 2026-07-08 decision, he&apos;s building most of the Phase 1 feature set himself (retrieval systems, animated table, transparency apparatus) rather than hiring it out — the two bounded specialist-engineer engagements (initial deployment setup, pre-public audit) stay hired regardless. The DIY line&apos;s cash cost is genuinely small (AI-assistance tokens), but it doesn&apos;t count Mark&apos;s own time, and there&apos;s a reserved-but-not-committed hire-out fallback in Bucket B specifically for the hardest pieces (retrieval systems, Runtime State Model) if the DIY attempt stalls on them.
A17: Sheets in this workbook | B17: Assumptions (every input, with sources) · Unit Economics (per-user-per-month cost buildup) · Phase 1 Budget (scenario totals).
A19: Repair note (2026-07-08)
A20: This file was found corrupted on disk (missing zip central directory — a truncated write, same failure mode diagnosed earlier in this project). It was repaired by recovering the raw XML streams directly, which were intact, and reassembling a valid archive around them. Every number and formula in this file is byte-exact recovered — nothing was recalculated or guessed. The exception: the shared-string text table itself was truncated near its end, so roughly the last third of the workbook's text labels (most of the Per-World Annual Cost tab and the Phase 1 Budget tab) could not be recovered verbatim and were rewritten from scratch, grounded in the recovered formulas and this project's own decision log rather than guessed blind. If any rewritten label reads oddly against what you remember writing, the formula and value beside it are still the original — trust those over the wording.

Sheet Assumptions
A1: Assumptions
A2: Blue = input, change freely. Every row is sourced in the Notes column.
A3: Assumption | B3: Value | C3: Unit | D3: Source / Note
A4: USAGE PATTERN
A5: Conversational exchanges per hour | B5: 20 | C5: turns/hour | D5: Working assumption — a real back-and-forth pace, not rapid chat. Set 2026-07-08.
A6: Hours of use per user per month | B6: 2 | C6: hours | D6: Baseline usage scenario used throughout this thread&apos;s cost discussion, 2026-07-08.
A7: Avg. Representatives responding per turn | B7: 1.3 | C7: multiplier | D7: Blended factor for a multi-world Table — some turns invoke more than one Representative. Estimate.
A9: LLM TOKENS PER TURN (per Representative invoked)
A10: World Capsule Core | B10: 4000 | C10: tokens | D10: Source: CiC_FrontEnd_Engineering_Specification_V1_1, Sec 2.1 — target 3,000-5,000 tokens, midpoint used.
A11: World Priority Layer | B11: 1200 | C11: tokens | D11: Estimate — Sec 2.2 describes content, gives no token target. Inferential/Thin.
A12: Retrieved chunks (lexicon/context/story) | B12: 900 | C12: tokens | D12: Estimate — Sec 2.3 target is 300-600 tokens/chunk; assumes ~1.5-2 chunks retrieved per turn on average.
A13: System / Facilitator prompt overhead | B13: 1500 | C13: tokens | D13: Estimate — not specified in source docs. Inferential/Thin.
A14: Avg. public transcript size (per turn) | B14: 4000 | C14: tokens | D14: Estimate — average transcript size across a ~40-turn, 2-hour session (starts at 0, ends ~8,000).
A15: Output tokens per response | B15: 200 | C15: tokens | D15: Estimate — a few sentences to a paragraph per response.
A17: LLM PRICING — Claude Sonnet 5 (working assumption; no runtime model chosen yet)
A18: Input price | B18: 2 | C18: $/M tokens | D18: Source: platform.claude.com/docs pricing page, accessed 2026-07-08. Sonnet 5, rate through Aug 31 2026.
A19: Output price | B19: 10 | C19: $/M tokens | D19: Same source.
A20: Prompt-cache read multiplier | B20: 0.1 | C20: x base input price | D20: Source: platform.claude.com/docs prompt-caching page, accessed 2026-07-08 — cache reads billed at 0.1x.
A22: LLM PRICING — Claude Opus (used for review passes, per the project&apos;s own review model)
A23: Opus input price | B23: 5 | C23: $/M tokens | D23: Source: platform.claude.com/docs pricing page, accessed 2026-07-08.
A24: Opus output price | B24: 25 | C24: $/M tokens | D24: Same source.
A26: WORLD CONSTRUCTION — build-time AI cost (research + drafting + review, one world)
A27: Drafting/research input tokens — low | B27: 800000 | C27: tokens | D27: Estimate — cumulative context across a full build thread (Docs 01-09, World Profile, deployment packaging). Inferential/Thin, no per-world token log exists.
A28: Drafting/research input tokens — high | B28: 3000000 | C28: tokens | D28: Same basis, upper bound — accounts for a long, iterative build with substantial re-reading of accumulated documents.
A29: Drafting/research output tokens — low | B29: 150000 | C29: tokens | D29: Estimate — final + intermediate draft content across ~9-11 major deliverables (Docs 01-09, World Profile, deployment package chunks).
A30: Drafting/research output tokens — high | B30: 400000 | C30: tokens | D30: Same basis, upper bound.
A31: Opus review-pass input tokens — low | B31: 150000 | C31: tokens | D31: Estimate — each review re-reads accumulated world documentation; assumes ~1-1.5 review passes per major document.
A32: Opus review-pass input tokens — high | B32: 500000 | C32: tokens | D32: Same basis, upper bound — assumes more review rounds and deeper re-reads.
A33: Opus review-pass output tokens — low | B33: 15000 | C33: tokens | D33: Estimate — written critique per review pass.
A34: Opus review-pass output tokens — high | B34: 50000 | C34: tokens | D34: Same basis, upper bound.
A36: VOICE (text-to-speech)
A37: AI-generated speech as share of session | B37: 0.5 | C37: fraction | D37: Working assumption — roughly half of session time is AI speaking, half participant.
A38: Voice price — unoptimized (ElevenLabs) | B38: 0.08 | C38: $/minute | D38: Source: elevenlabs.io/pricing/api, Speech Engine (conversational), accessed 2026-07-08.
A39: Voice price — optimized (Google Chirp 3: HD) | B39: 0.027 | C39: $/minute | D39: Derived from cloud.google.com/text-to-speech/pricing ($30/1M chars) at ~900 chars/min. Quality vs. ElevenLabs not yet A/B tested — see decision log.
A41: PHASE 1 USER SCENARIOS
A42: Low adoption | B42: 250 | C42: users | D42: Working assumption — a modest early public launch.
A43: Medium adoption | B43: 1500 | C43: users | D43: Working assumption.
A44: High adoption | B44: 10000 | C44: users | D44: Matches the scale point raised in this thread&apos;s discussion on 2026-07-08.
A46: EXTERNAL SCHOLARLY REVIEWERS — Constitution Article 31
A47: Worlds requiring review | B47: 5 | C47: worlds | D47: Phase 1 requires the full 5-world Ancient Church set table-ready, per CiC_L3A_Phase_Structure_V1.1.
...

Sheet Unit Economics
A1: Unit Economics — Cost per User per Month
A2: Green cells pull from the Assumptions tab. All formulas — change assumptions there, not here.
A4: Metric | B4: Optimized (caching + Google Chirp 3 HD voice) | C4: Unoptimized (no caching + ElevenLabs)
A5: TEXT / LLM
A6: Turns per month | B6: =Assumptions!$B$5*Assumptions!$B$6 -> 40 | C6: =Assumptions!$B$5*Assumptions!$B$6 -> 40
A7: Fixed (cacheable) tokens/turn | B7: =Assumptions!$B$10+Assumptions!$B$11+Assumptions!$B$13 -> 6700 | C7: =Assumptions!$B$10+Assumptions!$B$11+Assumptions!$B$13 -> 6700
A8: Non-cacheable tokens/turn (retrieval + transcript) | B8: =Assumptions!$B$12+Assumptions!$B$14 -> 4900 | C8: =Assumptions!$B$12+Assumptions!$B$14 -> 4900
A9: Billed input tokens/turn | B9: =B7*Assumptions!$B$20+B8 -> 5570 | C9: =C7+C8 -> 11600
A10: Input cost/turn ($) | B10: =B9/1000000*Assumptions!$B$18 -> 0.01114 | C10: =C9/1000000*Assumptions!$B$18 -> 0.0232
A11: Output cost/turn ($) | B11: =Assumptions!$B$15/1000000*Assumptions!$B$19 -> 0.002 | C11: =Assumptions!$B$15/1000000*Assumptions!$B$19 -> 0.002
A12: LLM cost/turn, incl. multi-Rep factor ($) | B12: =(B10+B11)*Assumptions!$B$7 -> 0.017082 | C12: =(C10+C11)*Assumptions!$B$7 -> 0.03276
A13: LLM cost per user per month | B13: =B12*B6 -> 0.68328 | C13: =C12*C6 -> 1.3104
A15: VOICE
A16: AI speech minutes per month | B16: =Assumptions!$B$37*Assumptions!$B$6*60 -> 60 | C16: =Assumptions!$B$37*Assumptions!$B$6*60 -> 60
A17: Voice cost per user per month | B17: =B16*Assumptions!$B$39 -> 1.62 | C17: =C16*Assumptions!$B$38 -> 4.8
A19: TOTAL — USAGE COST PER USER
A20: Total per user per month | B20: =B13+B17 -> 2.30328 | C20: =C13+C17 -> 6.1104
A21: Total per user per year | B21: =B20*12 -> 27.63936 | C21: =C20*12 -> 73.3248

Sheet Per-World Annual Cost
A1: Church in Conversation — Per-World Annual Cost
A2: Draft v0.1 · Built 2026-07-08 · What one formation world costs to build and run, one year, at three illustrative audience sizes.
A4: Line Item | B4: Low | C4: High | D4: Note
A5: WORLD CONSTRUCTION — build-time AI cost (one-time, per world)
A6: Drafting / research (Claude Sonnet) | B6: =Assumptions!$B$27/1000000*Assumptions!$B$18+Assumptions!$B$29/1000000*Assumptions!$B$19 -> 3.1 | C6: =Assumptions!$B$28/1000000*Assumptions!$B$18+Assumptions!$B$30/1000000*Assumptions!$B$19 -> 10 | D6: Sonnet input + output token cost for one world's research and drafting pass — see Assumptions tab for the token-volume basis.
A7: Review passes (Claude Opus) | B7: =Assumptions!$B$31/1000000*Assumptions!$B$23+Assumptions!$B$33/1000000*Assumptions!$B$24 -> 1.125 | C7: =Assumptions!$B$32/1000000*Assumptions!$B$23+Assumptions!$B$34/1000000*Assumptions!$B$24 -> 3.75 | D7: Opus input + output token cost for review passes on one world — see Assumptions tab.
A8: World construction — subtotal | B8: =B6+B7 -> 4.225 | C8: =C6+C7 -> 13.75 | D8: Genuinely small — build-time AI cost is a rounding error next to the human-cost lines (external review, engineering, hosting) below. Confirms the project's own intuition rather than contradicting it.
A10: ARTICLE 31 EXTERNAL SCHOLARLY REVIEW (one-time, per world)
A11: Cost per world | B11: =Assumptions!$B$48 -> 500 | C11: =Assumptions!$B$49 -> 3500 | D11: Relational/honorarium (low) to formal paid consulting (high) — see Assumptions tab.
A13: RUNTIME — annual usage cost, scales with audience
A14: Small audience (~50 users/year) | B14: =Assumptions!$B$52*'Unit Economics'!$B$21 -> 1381.968 | C14: =Assumptions!$B$52*'Unit Economics'!$C$21 -> 3666.24 | D14: Illustrative — a single world used by a modest number of people over a year.
A15: Medium audience (~250 users/year) | B15: =Assumptions!$B$53*'Unit Economics'!$B$21 -> 6909.84 | C15: =Assumptions!$B$53*'Unit Economics'!$C$21 -> 18331.2 | D15: Illustrative — matches the Phase 1 Budget tab's Low-adoption scenario.
A16: Large audience (~1,000 users/year) | B16: =Assumptions!$B$54*'Unit Economics'!$B$21 -> 27639.36 | C16: =Assumptions!$B$54*'Unit Economics'!$C$21 -> 73324.8 | D16: Illustrative.
A18: ONE WORLD, ONE YEAR — HEADLINE (medium/250-user audience)
A19: Total — construction + review + medium-audience runtime | B19: =B8+B11+B15 -> 7414.065 | C19: =C8+C11+C15 -> 21844.95 | D19: = World construction subtotal + Article 31 review (low) + medium-audience runtime.
A21: Excludes hosting/platform base fee and any stipend for Mark — those are workbook-wide costs tracked on the Phase 1 Budget tab, not per-world costs.

Sheet Phase 1 Budget
A1: Church in Conversation — Phase 1 Budget
A2: Draft v0.1 · Built 2026-07-08, revised — Mark builds most of it himself; no stipend included. For Mark's review, not yet final.
A4: BUCKET A — USAGE-SCALING COST (annual, recurring — needs revenue that scales with usage)
A5: Adoption Scenario | B5: Users | C5: Optimized — Annual | D5: Unoptimized — Annual
A6: Low adoption | B6: =Assumptions!$B$42 -> 250 | C6: =B6*'Unit Economics'!$B$21 -> 6909.84 | D6: =B6*'Unit Economics'!$C$21 -> 18331.2
A7: Medium adoption | B7: =Assumptions!$B$43 -> 1500 | C7: =B7*'Unit Economics'!$B$21 -> 41459.04 | D7: =B7*'Unit Economics'!$C$21 -> 109987.2
A8: High adoption | B8: =Assumptions!$B$44 -> 10000 | C8: =B8*'Unit Economics'!$B$21 -> 276393.6 | D8: =B8*'Unit Economics'!$C$21 -> 733248
A10: BUCKET B — FIXED MINISTRY & BUILD-OUT COST (scales with worlds/features, not user count)
A11: Line Item | B11: Timing | C11: Low | D11: High | E11: Note
A12: External scholarly reviewers (Article 31) | B12: One-time | C12: =Assumptions!$B$47*Assumptions!$B$48 -> 2500 | D12: =Assumptions!$B$47*Assumptions!$B$49 -> 17500 | E12: 5 worlds x $500-3,500/world — see Assumptions tab.
A13: Engagement One — initial deployment setup (hired) | B13: One-time | C13: =Assumptions!$B$57*Assumptions!$B$60 -> 5000 | D13: =Assumptions!$B$58*Assumptions!$B$61 -> 16000 | E13: Bounded, hired engagement once the platform is chosen — per Front-End Spec Sec 6. Placeholder pending real scoping.
A14: Engagement Two — pre-public-availability audit (hired) | B14: One-time | C14: =Assumptions!$B$59*Assumptions!$B$60 -> 7500 | D14: =Assumptions!$B$59*Assumptions!$B$61 -> 12000 | E14: Must be an engineer with no prior build involvement — Front-End Spec Sec 6. Hired regardless of the DIY decision below.
A15: DIY build — Mark's own AI-assisted engineering time (API cost only) | B15: One-time | C15: =Assumptions!$B$62/1000000*Assumptions!$B$18+Assumptions!$B$64/1000000*Assumptions!$B$19 -> 30 | D15: =Assumptions!$B$63/1000000*Assumptions!$B$18+Assumptions!$B$65/1000000*Assumptions!$B$19 -> 110 | E15: Raw Claude Code-style token cost for Mark building the Phase 1 feature set himself — see Assumptions tab. Excludes Mark's own unpaid time.
A16: Hosting / platform base fee (annual) | B16: Annual | C16: =Assumptions!$B$70*12 -> 1200 | D16: =Assumptions!$B$71*12 -> 6000 | E16: Placeholder — no platform chosen yet. Excludes AI usage cost, counted separately.
A17: Bucket B subtotal (Year 1) | C17: =C12+C13+C14+C15+C16 -> 16230 | D17: =D12+D13+D14+D15+D16 -> 51610
A18: Hire-out fallback reserve (hardest pieces only, if DIY stalls) | B18: Reserve, not committed | C18: =Assumptions!$B$66*Assumptions!$B$60 -> 7500 | D18: =Assumptions!$B$67*Assumptions!$B$61 -> 30000 | E18: Not in the subtotal above. Retrieval systems + Runtime State Model specifically, if DIY stalls on these — roughly a third to half of a full hired build-out.
A20: Not included above — legal/entity formation (contingent on the legal-structure decision, see the 2026-07-08 bridge memo):
A21: Fiscal sponsor fee | C21: =Assumptions!$B$74 -> 0.075 | E21: Applied to total funds raised, not a fixed dollar amount — only if fiscal sponsorship is the active path.
A22: Nonprofit filing (one-time, if filing directly instead) | C22: =Assumptions!$B$75 -> 1500
A24: TOTAL PHASE 1 FIRST-YEAR BUDGET (Bucket A + Bucket B, excludes legal/entity fee and any stipend for Mark)
A25: Scenario | C25: Total — Year 1 | E25: Note
A26: Lean case — Low adoption, DIY engineering, minimum Bucket B | C26: =C6+C17 -> 23139.84
A27: Planning estimate — Medium adoption, blended DIY/hire-out, blended Bucket B | C27: =C7+(C17+D17)/2 -> 75379.04
A28: Conservative case — High adoption, full hire-out fallback engaged, maximum Bucket B | C28: =D8+D17 -> 784858
A30: Excludes: any stipend for Mark; legal/entity fee (contingent, see above). DIY engineering cost above is API/token cost only — Mark's own time is not priced. If the hire-out fallback reserve is engaged, add it to Bucket B before totaling.
