Workbook

Sheet Read Me
A1: The Church in Conversation — Build-Approach Budget Proposals
A2: Draft v0.1 · Built 2026-07-08 · For Mark's review, not yet final
A4: What this is
A5: Four budget proposals answering one question: who builds the front end, and how much future-proofing to pay for while doing it. Requested 2026-07-08 as a direct follow-on to the Front-End Engineering Considerations Catalog (Project-Reference) — Proposals 3 and 4 are literally that catalog's "lean vs. long-term-in-mind" question, priced out.
A7: How this relates to the existing Phase 1 Budget workbook
A8: This workbook does not re-derive numbers that already exist. Usage economics (Bucket A: LLM + voice cost per user), external-reviewer cost, and the base engineering build-out range all come directly from Ministry/Funding/CiC_Phase1_Budget_V0_1_DRAFT.xlsx (built 2026-07-08, same repo). This workbook adds what that one doesn't cover: the DIY/learn-as-you-go path, and the dollar cost of the six growth-readiness items in the Engineering Considerations Catalog.
A10: The four proposals, as asked
A11: 1) Hire a front-end engineer to build it. 2) The tools and systems to build it yourself, learning as you go. 3) Prototype + Phase 1 only — lean/bounded, not architected for growth beyond that. 4) Prototype + Phase 1, built with long-term growth in mind. Proposals 1–2 answer "who builds it"; Proposals 3–4 answer "how much future-proofing." Because those are two different questions, each of the four proposal columns on the Proposals Compared tab shows both the lean and long-term-in-mind engineering cost (Props 1–2) or both the hired and DIY engineering cost (Props 3–4), so every column is a complete, self-contained answer rather than assuming your choice on the other axis.
A13: Scope
A14: All four proposals are scoped to reaching Phase 1 launch ("Conversations with the Early Church," 5 worlds, public access begins) at launch-scale adoption (250 users, the existing workbook's "Low adoption" scenario) — not Phase 2+ growth. Ongoing usage cost beyond Year 1, and adoption above 250 users, are covered by the existing Phase 1 Budget workbook's Medium/High scenarios; not repeated here.
A16: What it deliberately excludes
A17: No stipend for Mark, matching the existing workbook's explicit exclusion. No legal/entity formation cost (fiscal sponsor fee or nonprofit filing) — those are contingent on the org-funding thread's still-open legal-structure decision, tracked separately.
... A26: Assumptions (every input, sourced) · Growth-Readiness Increment (the six catalog items, itemized in hours) · Proposals Compared (the four proposals, side by side).

Sheet Assumptions
A1: Assumptions
A2: Blue = input, change freely. Every row is sourced in the Notes column.
A4: Assumption | B4: Value | C4: Unit | D4: Source / Note
A6: USAGE PATTERN — reused from CiC_Phase1_Budget_V0_1_DRAFT.xlsx (2026-07-08)
A7: Conversational exchanges per hour | B7: 20 | C7: turns/hour | D7: Reused from existing Phase 1 Budget workbook, Assumptions tab.
A8: Hours of use per user per month | B8: 2 | C8: hours | D8: Reused.
A9: Avg. Representatives responding per turn | B9: 1.3 | C9: multiplier | D9: Reused.
A11: LLM TOKENS PER TURN (per Representative invoked) — reused
A12: World Capsule Core | B12: 4000 | C12: tokens | D12: Reused. Source: CiC_FrontEnd_Engineering_Specification_V1_1, Sec 2.1.
A13: World Priority Layer | B13: 1200 | C13: tokens | D13: Reused.
A14: Retrieved chunks | B14: 900 | C14: tokens | D14: Reused.
A15: System / Facilitator prompt overhead | B15: 1500 | C15: tokens | D15: Reused.
A16: Avg. public transcript size per turn | B16: 4000 | C16: tokens | D16: Reused.
A17: Output tokens per response | B17: 200 | C17: tokens | D17: Reused.
A19: LLM PRICING — Claude Sonnet 5 — reused
A20: Input price | B20: 2 | C20: $/M tokens | D20: Reused. Source: platform.claude.com/docs, accessed 2026-07-08.
A21: Output price | B21: 10 | C21: $/M tokens | D21: Reused.
A22: Prompt-cache read multiplier | B22: 0.1 | C22: x base input price | D22: Reused. Cache reads billed at 0.1x.
A24: VOICE (text-to-speech) — reused
A25: AI-generated speech as share of session | B25: 0.5 | C25: fraction | D25: Reused.
A26: Voice price — unoptimized (ElevenLabs) | B26: 0.08 | C26: $/minute | D26: Reused. Source: elevenlabs.io/pricing/api, accessed 2026-07-08.
A27: Voice price — optimized (Google Chirp 3: HD) | B27: 0.027 | C27: $/minute | D27: Reused. Derived from cloud.google.com/text-to-speech/pricing.
A29: LAUNCH-SCALE ADOPTION (Phase 1 launch, not later growth)
A30: Launch-scale users (Year 1) | B30: 250 | C30: users | D30: Reused — matches existing workbook's "Low adoption" scenario. These four proposals price reaching launch, not post-launch scale-up.
A32: ARTICLE 31 EXTERNAL SCHOLARLY REVIEWERS — reused
A33: Worlds requiring review | B33: 5 | C33: worlds | D33: Reused. Full 5-world Ancient Church set, per Phase Structure V1.1.
A34: Cost per world — relational/honorarium | B34: 500 | C34: $/world | D34: Reused. Inferential/Thin.
A35: Cost per world — formal paid consulting | B35: 3500 | C35: $/world | D35: Reused. Inferential/Thin.
A37: ENGINEERING — BASE FEATURE BUILD-OUT (lean/bounded scope) — reused
A38: Phase 1 feature build-out — low estimate | B38: 150 | C38: hours | D38: Reused. Placeholder pending real scoping — no Deployment Standards doc exists yet.
A39: Phase 1 feature build-out — high estimate | B39: 400 | C39: hours | D39: Reused.
A40: Engagement Two — pre-public-availability audit | B40: 60 | C40: hours | D40: Reused. Hired regardless of build path — see Read Me.
A41: Engineer rate — low | B41: 125 | C41: $/hour | D41: Reused. Source: zenvanriel.com freelance AI engineer rate guide, accessed 2026-07-08.
A42: Engineer rate — high | B42: 200 | C42: $/hour | D42: Reused.
A44: HOSTING / PLATFORM — reused
A45: Monthly base hosting — low | B45: 100 | C45: $/month | D45: Reused. Placeholder — no platform chosen yet.
A46: Monthly base hosting — high | B46: 500 | C46: $/month | D46: Reused.
A48: DIY TOOLING (Proposal 2 — new) — sourced 2026-07-08
A49: AI coding assistant — light use (Claude Code, Pro plan) | B49: 20 | C49: $/month | D49: Documented. Source: Anthropic Claude Code pricing, accessed 2026-07-08.
A50: AI coding assistant — heavy use (Claude Code, Max 5x plan) | B50: 100 | C50: $/month | D50: Documented. Realistic for a beginner doing heavy iterative AI-assisted building. Same source.
...

Sheet Growth-Readiness Increment
A1: Growth-Readiness Increment — what "long-term-in-mind" actually buys
A2: Itemized hours for the six items in the Engineering Considerations Catalog (Project-Reference/CiC_Engineering_Considerations_Catalog_V1_0.md, 2026-07-08). Inferential/Thin — reasoned estimates, not a quote.
A4: Catalog item | B4: Low hrs | C4: High hrs | D4: Why this many hours
A5: World data schema readiness (temporal range, region, "shaped-by" relationship fields on every world record) | B5: 6 | C5: 10 | D5: Data-modeling only — no UI work required at Phase 1. Cheap because it's fields on a record, not a feature.
A6: Retrieval behind a clean interface (rule-based now, swappable to semantic search later without touching every caller) | B6: 10 | C6: 20 | D6: One extra layer of indirection around the Layer 7 retrieval call — architectural discipline, not new functionality.
A7: Role/entitlement field + lightweight optional accounts (so a future paid tier is a flag flip, not a rebuild) | B7: 12 | C7: 25 | D7: The most substantial item — even a minimal optional sign-in touches session handling, which doesn't otherwise need to exist at Phase 1.
A8: Voice pipeline built as the real architecture (cheap voice selected now, not a throwaway version) | B8: 5 | C8: 10 | D8: Small increment if the pipeline shape is designed right the first time — most of this cost is in avoiding a wrong shortcut, not extra building.
A9: Conversation-logging / privacy policy given one coherent technical implementation (not two colliding defaults) | B9: 8 | C9: 15 | D9: Structured, consent-aware logging takes modestly more engineering than logging everything or nothing; the policy-writing itself is separate, non-engineering work.
A10: World-content versioning scaffold (so a content update doesn't require a full redeploy or break a live session) | B10: 6 | C10: 12 | D10: A version tag on the Runtime State Model's session record — cheap now, since that model doesn't exist yet to retrofit.
A11: Growth-readiness increment — subtotal | B11: =SUM(B5:B10) -> 47 | C11: =SUM(C5:C10) -> 92 | D11: Feeds Assumptions tab — see Read Me for how this rolls into Proposals Compared.

Sheet Proposals Compared
A1: Proposals Compared
A2: Every column is self-contained: each proposal answers its own question fully (Props 1–2 show both the lean and long-term-in-mind engineering cost; Props 3–4 show both the hired and DIY engineering cost), so no proposal's total assumes an answer to the other axis.
A4: Line Item | B4: Proposal 1: Hire a Front-End Engineer | D4: Proposal 2: DIY — Tools & Learn as You Go | F4: Proposal 3: Phase 1 Only — Lean / Bounded | H4: Proposal 4: Phase 1 — Long-Term-in-Mind | J4: Note
B5: Low | C5: High | D5: Low | E5: High | F5: Low | G5: High | H5: Low | I5: High
A6: ENGINEERING — FEATURE BUILD-OUT
A7: Feature build-out — lean/bounded scope, if HIRED | B7: =Assumptions!B38*Assumptions!B41 -> 18750 | C7: =Assumptions!B39*Assumptions!B42 -> 80000 | D7: — | E7: — | F7: =Assumptions!B38*Assumptions!B41 -> 18750 | G7: =Assumptions!B39*Assumptions!B42 -> 80000 | H7: — | I7: — | J7: 150–400 hrs at $125–200/hr. Reused base build-out estimate — pending real scoping (no Deployment Standards doc yet).
A8: Feature build-out — lean/bounded scope, if DIY (your own unpaid time) | B8: — | C8: — | D8: 0 | E8: 0 | F8: 0 | G8: 0 | H8: — | I8: — | J8: Cash cost is $0 — the real cost is your own time, captured in the Calendar Time rows below, not here.
A9: Feature build-out — long-term-in-mind scope, if HIRED | B9: =(Assumptions!B38+'Growth-Readiness Increment'!B11)*Assumptions!B41 -> 24625 | C9: =(Assumptions!B39+'Growth-Readiness Increment'!C11)*Assumptions!B42 -> 98400 | D9: — | E9: — | F9: — | G9: — | H9: =(Assumptions!B38+'Growth-Readiness Increment'!B11)*Assumptions!B41 -> 24625 | I9: =(Assumptions!B39+'Growth-Readiness Increment'!C11)*Assumptions!B42 -> 98400 | J9: Base 150–400 hrs + the 45–90 hr Growth-Readiness Increment (see that tab) at $125–200/hr.
A10: Feature build-out — long-term-in-mind scope, if DIY (your own unpaid time) | B10: — | C10: — | D10: 0 | E10: 0 | F10: — | G10: — | H10: 0 | I10: 0 | J10: Cash cost is still $0 as DIY — but learning to apply the growth-readiness items adds real calendar time (see below), more than it adds cash.
A12: HIRED REGARDLESS OF PATH (independent audit; content-governance reviewers — apply to all four proposals equally)
A13: Pre-public-availability audit (Engagement Two — independent engineer, hired regardless) | B13: =Assumptions!B40*Assumptions!B41 -> 7500 | C13: =Assumptions!B40*Assumptions!B42 -> 12000 | D13: =Assumptions!B40*Assumptions!B41 -> 7500 | E13: =Assumptions!B40*Assumptions!B42 -> 12000 | F13: =Assumptions!B40*Assumptions!B41 -> 7500 | G13: =Assumptions!B40*Assumptions!B42 -> 12000 | H13: =Assumptions!B40*Assumptions!B41 -> 7500 | I13: =Assumptions!B40*Assumptions!B42 -> 12000 | J13: 60 hrs at $125–200/hr. Must be someone without prior build involvement — Eng. Spec Sec. 6. Even the DIY path cannot skip this.
A14: External scholarly reviewers (Article 31 — content governance, independent of front-end build path) | B14: =Assumptions!B33*Assumptions!B34 -> 2500 | C14: =Assumptions!B33*Assumptions!B35 -> 17500 | D14: =Assumptions!B33*Assumptions!B34 -> 2500 | E14: =Assumptions!B33*Assumptions!B35 -> 17500 | F14: =Assumptions!B33*Assumptions!B34 -> 2500 | G14: =Assumptions!B33*Assumptions!B35 -> 17500 | H14: =Assumptions!B33*Assumptions!B34 -> 2500 | I14: =Assumptions!B33*Assumptions!B35 -> 17500 | J14: 5 worlds x $500–3,500/world. Governs world content, not who builds the front end — same cost under all four proposals.
A16: PLATFORM & USAGE (apply to all four equally)
A17: Production hosting / platform base fee (annual) | B17: =Assumptions!B45*12 -> 1200 | C17: =Assumptions!B46*12 -> 6000 | D17: =Assumptions!B45*12 -> 1200 | E17: =Assumptions!B46*12 -> 6000 | F17: =Assumptions!B45*12 -> 1200 | G17: =Assumptions!B46*12 -> 6000 | H17: =Assumptions!B45*12 -> 1200 | I17: =Assumptions!B46*12 -> 6000 | J17: No platform chosen yet. Same placeholder range regardless of build path — this is what running it costs, not building it.
A18: Usage cost, Year 1 (LLM + voice, launch-scale ~250 users) | B18: =Assumptions!B82 -> 6909.84 | C18: =Assumptions!B83 -> 18331.2 | D18: =Assumptions!B82 -> 6909.84 | E18: =Assumptions!B83 -> 18331.2 | F18: =Assumptions!B82 -> 6909.84 | G18: =Assumptions!B83 -> 18331.2 | H18: =Assumptions!B82 -> 6909.84 | I18: =Assumptions!B83 -> 18331.2 | J18: Low = optimized (caching + Google Chirp 3 HD). High = unoptimized (no caching + ElevenLabs). Same regardless of build path.
A20: DIY-SPECIFIC COSTS (populated wherever DIY is the build path — Prop 2, and the DIY sub-case within Props 3/4)
A21: DIY tooling & dev subscriptions (annual): AI coding assistant + dev hosting + dev backend | B21: — | C21: — | D21: =(Assumptions!B49+Assumptions!B51+Assumptions!B53)*12 -> 480 | E21: =(Assumptions!B50+Assumptions!B52+Assumptions!B54)*12 -> 2304 | F21: =(Assumptions!B49+Assumptions!B51+Assumptions!B53)*12 -> 480 | G21: =(Assumptions!B50+Assumptions!B52+Assumptions!B54)*12 -> 2304 | H21: =(Assumptions!B49+Assumptions!B51+Assumptions!B53)*12 -> 480 | I21: =(Assumptions!B50+Assumptions!B52+Assumptions!B54)*12 -> 2304 | J21: Claude Code ($20–100/mo) + Vercel Pro dev usage ($20–67/mo) + Supabase ($0–25/mo). Same cost whenever DIY is the chosen path, regardless of scope.
A22: Occasional expert consult — safety valve for getting unstuck | B22: — | C22: — | D22: =Assumptions!B55*Assumptions!B41 -> 1250 | E22: =Assumptions!B56*Assumptions!B42 -> 4000 | F22: =Assumptions!B55*Assumptions!B41 -> 1250 | G22: =Assumptions!B56*Assumptions!B42 -> 4000 | H22: =Assumptions!B55*Assumptions!B41 -> 1250 | I22: =Assumptions!B56*Assumptions!B42 -> 4000 | J22: 10–20 hrs at the same $125–200/hr contractor rate — a buffer, not a plan. Same whenever DIY is chosen.
A24: TOTAL — YEAR 1 CASH COST (four scenarios, so no total silently adds two mutually-exclusive engineering choices together)
A25: TOTAL, lean scope, if HIRED | B25: =B7+B13+B14+B17+B18 -> 36859.84 | C25: =C7+C13+C14+C17+C18 -> 133831.2 | D25: — | E25: — | F25: =F7+F13+F14+F17+F18 -> 36859.84 | G25: =G7+G13+G14+G17+G18 -> 133831.2 | H25: — | I25: — | J25: build-out(lean,hired) + audit + reviewers + hosting + usage. Populated for Prop 1 and Prop 3.
A26: TOTAL, lean scope, if DIY | B26: — | C26: — | D26: =D8+D13+D14+D17+D18+D21+D22 -> 19839.84 | E26: =E8+E13+E14+E17+E18+E21+E22 -> 60135.2 | F26: =F8+F13+F14+F17+F18+F21+F22 -> 19839.84 | G26: =G8+G13+G14+G17+G18+G21+G22 -> 60135.2 | H26: — | I26: — | J26: $0 build-out + audit + reviewers + hosting + usage + DIY tooling + consult buffer. Populated for Prop 2 and Prop 3.
A27: TOTAL, long-term-in-mind scope, if HIRED | B27: =B9+B13+B14+B17+B18 -> 42734.84 | C27: =C9+C13+C14+C17+C18 -> 152231.2 | D27: — | E27: — | F27: — | G27: — | H27: =H9+H13+H14+H17+H18 -> 42734.84 | I27: =I9+I13+I14+I17+I18 -> 152231.2 | J27: build-out(long-term,hired) + audit + reviewers + hosting + usage. Populated for Prop 1 and Prop 4.
A28: TOTAL, long-term-in-mind scope, if DIY | B28: — | C28: — | D28: =D10+D13+D14+D17+D18+D21+D22 -> 19839.84 | E28: =E10+E13+E14+E17+E18+E21+E22 -> 60135.2 | F28: — | G28: — | H28: =H10+H13+H14+H17+H18+H21+H22 -> 19839.84 | I28: =I10+I13+I14+I17+I18+I21+I22 -> 60135.2 | J28: $0 build-out + audit + reviewers + hosting + usage + DIY tooling + consult buffer. Populated for Prop 2 and Prop 4.
A30: ESTIMATED CALENDAR TIME TO PHASE 1 LAUNCH (Inferential/Thin — see Assumptions tab)
A31: Calendar time — lean scope, if HIRED | B31: =Assumptions!B59 -> 1.5–6 | C31: =Assumptions!B59 -> 1.5–6 | D31: — | E31: — | F31: =Assumptions!B59 -> 1.5–6 | G31: =Assumptions!B59 -> 1.5–6 | H31: — | I31: — | J31: Same underlying estimate shown from both Prop 1 and Prop 3's entry point.
A32: Calendar time — lean scope, if DIY | B32: — | C32: — | D32: =Assumptions!B61 -> 3–12 | E32: =Assumptions!B61 -> 3–12 | F32: =Assumptions!B61 -> 3–12 | G32: =Assumptions!B61 -> 3–12 | H32: — | I32: — | J32: Same underlying estimate shown from both Prop 2 and Prop 3's entry point.
A33: Calendar time — long-term-in-mind scope, if HIRED | B33: =Assumptions!B60 -> 2–7.5 | C33: =Assumptions!B60 -> 2–7.5 | D33: — | E33: — | F33: — | G33: — | H33: =Assumptions!B60 -> 2–7.5 | I33: =Assumptions!B60 -> 2–7.5 | J33: Same underlying estimate shown from both Prop 1 and Prop 4's entry point.
A34: Calendar time — long-term-in-mind scope, if DIY | B34: — | C34: — | D34: =Assumptions!B62 -> 6–18 | E34: =Assumptions!B62 -> 6–18 | F34: — | G34: — | H34: =Assumptions!B62 -> 6–18 | I34: =Assumptions!B62 -> 6–18 | J34: Same underlying estimate shown from both Prop 2 and Prop 4's entry point.
